[ 2024-12-25 14:15:32,083 ] 28 src.logger.custom_logging - INFO - >>>>>> stage Prepare Base Model stage started <<<<<<
[ 2024-12-25 14:15:32,084 ] 45 src.logger.custom_logging - INFO - yaml file: config/config.yaml loaded successfully
[ 2024-12-25 14:15:32,085 ] 45 src.logger.custom_logging - INFO - yaml file: params.yaml loaded successfully
[ 2024-12-25 14:15:32,086 ] 65 src.logger.custom_logging - INFO - created directory at: artifacts
[ 2024-12-25 14:15:32,086 ] 65 src.logger.custom_logging - INFO - created directory at: artifacts/data_transformation
[ 2024-12-25 14:15:32,086 ] 19 src.logger.custom_logging - INFO - Creating data transformation pipeline
[ 2024-12-25 14:15:32,086 ] 33 src.logger.custom_logging - ERROR - object.__init__() takes exactly one argument (the instance to initialize)
Traceback (most recent call last):
  File "/Users/akashmukherjee/Programming/Internship/IMMERSIVIFY/Titanic/src/pipeline/stage_02_data_transform_pipe.py", line 22, in main
    data_transformation.initiate_data_transformation()
TypeError: DataTransformation.initiate_data_transformation() missing 2 required positional arguments: 'train_path' and 'test_path'

During handling of the above exception, another exception occurred:

Traceback (most recent call last):
  File "/Users/akashmukherjee/Programming/Internship/IMMERSIVIFY/Titanic/src/pipeline/stage_02_data_transform_pipe.py", line 30, in <module>
    obj.main()
  File "/Users/akashmukherjee/Programming/Internship/IMMERSIVIFY/Titanic/src/pipeline/stage_02_data_transform_pipe.py", line 24, in main
    raise CustomException(e,sys)
         ^^^^^^^^^^^^^^^^^^^^^^
  File "/Users/akashmukherjee/Programming/Internship/IMMERSIVIFY/Titanic/src/exceptions/expection.py", line 17, in __init__
    super().__init__(error_msg)
TypeError: object.__init__() takes exactly one argument (the instance to initialize)
